[2025-03-06 13:49:38,252] [test_runner.py(164)]: 预计并发线程数：1
[2025-03-06 13:49:38,253] [result.py(73)]: 开始测试： testlogin (login_test_resolve.Auto_Test.testlogin)
[2025-03-06 13:49:44,663] [login_test_resolve.py(54)]: shoplazza FAIL —— data : ['shoplazza', 'customer@email.us', '00003195']
[2025-03-06 13:50:30,290] [login_test_resolve.py(52)]: shoplazza PASS
[2025-03-06 13:50:34,931] [login_test_resolve.py(54)]: shoplazza FAIL —— data : ['shoplazza', '+8613106683312', '00003195']
[2025-03-06 13:50:37,374] [login_test_resolve.py(52)]: shoplazza PASS
[2025-03-06 13:50:40,724] [login_test_resolve.py(52)]: onekingslane PASS
[2025-03-06 13:50:43,549] [login_test_resolve.py(52)]: onekingslane PASS
[2025-03-06 13:50:48,061] [login_test_resolve.py(52)]: onekingslane PASS
[2025-03-06 13:50:50,835] [login_test_resolve.py(52)]: onekingslane PASS
[2025-03-06 13:50:53,779] [login_test_resolve.py(52)]: curtsy PASS
[2025-03-06 13:50:56,211] [login_test_resolve.py(52)]: curtsy PASS
[2025-03-06 13:50:59,311] [login_test_resolve.py(52)]: curtsy PASS
[2025-03-06 13:51:02,097] [login_test_resolve.py(52)]: curtsy PASS
[2025-03-06 13:51:04,656] [login_test_resolve.py(52)]: sidelineswap PASS
[2025-03-06 13:51:07,061] [login_test_resolve.py(52)]: sidelineswap PASS
[2025-03-06 13:51:10,456] [login_test_resolve.py(52)]: sidelineswap PASS
[2025-03-06 13:51:13,753] [login_test_resolve.py(52)]: sidelineswap PASS
[2025-03-06 13:51:16,521] [login_test_resolve.py(52)]: shoppremiumoutlets PASS
[2025-03-06 13:51:19,308] [login_test_resolve.py(52)]: shoppremiumoutlets PASS
[2025-03-06 13:51:21,879] [login_test_resolve.py(52)]: shoppremiumoutlets PASS
[2025-03-06 13:51:24,329] [login_test_resolve.py(52)]: shoppremiumoutlets PASS
[2025-03-06 13:51:26,500] [login_test_resolve.py(52)]: backcountry PASS
[2025-03-06 13:51:29,099] [login_test_resolve.py(52)]: backcountry PASS
[2025-03-06 13:51:31,320] [login_test_resolve.py(52)]: backcountry PASS
[2025-03-06 13:51:33,944] [login_test_resolve.py(52)]: backcountry PASS
[2025-03-06 13:51:36,705] [login_test_resolve.py(52)]: chicv PASS
[2025-03-06 13:51:39,346] [login_test_resolve.py(52)]: chicv PASS
[2025-03-06 13:51:42,314] [login_test_resolve.py(52)]: chicv PASS
[2025-03-06 13:51:45,062] [login_test_resolve.py(52)]: chicv PASS
[2025-03-06 13:51:47,687] [login_test_resolve.py(52)]: commentsold PASS
[2025-03-06 13:51:49,893] [login_test_resolve.py(52)]: commentsold PASS
[2025-03-06 13:51:52,295] [login_test_resolve.py(52)]: commentsold PASS
[2025-03-06 13:51:56,462] [login_test_resolve.py(52)]: commentsold PASS
[2025-03-06 13:51:59,779] [login_test_resolve.py(52)]: ctbids PASS
[2025-03-06 13:52:02,273] [login_test_resolve.py(52)]: ctbids PASS
[2025-03-06 13:52:04,490] [login_test_resolve.py(52)]: ctbids PASS
[2025-03-06 13:52:07,871] [login_test_resolve.py(52)]: ctbids PASS
[2025-03-06 13:52:10,818] [login_test_resolve.py(52)]: goodwillfinds PASS
[2025-03-06 13:52:13,616] [login_test_resolve.py(52)]: goodwillfinds PASS
[2025-03-06 13:52:16,006] [login_test_resolve.py(52)]: goodwillfinds PASS
[2025-03-06 13:52:18,543] [login_test_resolve.py(52)]: goodwillfinds PASS
[2025-03-06 13:52:21,147] [login_test_resolve.py(52)]: jeulia PASS
[2025-03-06 13:52:23,835] [login_test_resolve.py(52)]: jeulia PASS
[2025-03-06 13:52:26,126] [login_test_resolve.py(52)]: jeulia PASS
[2025-03-06 13:52:28,658] [login_test_resolve.py(52)]: jeulia PASS
[2025-03-06 13:52:31,490] [login_test_resolve.py(52)]: luxedujour PASS
[2025-03-06 13:52:34,064] [login_test_resolve.py(52)]: luxedujour PASS
[2025-03-06 13:52:36,597] [login_test_resolve.py(52)]: luxedujour PASS
[2025-03-06 13:52:39,345] [login_test_resolve.py(52)]: luxedujour PASS
[2025-03-06 13:52:41,767] [login_test_resolve.py(52)]: poizon PASS
[2025-03-06 13:52:43,989] [login_test_resolve.py(52)]: poizon PASS
[2025-03-06 13:52:46,351] [login_test_resolve.py(52)]: poizon PASS
[2025-03-06 13:52:48,629] [login_test_resolve.py(52)]: poizon PASS
[2025-03-06 13:52:51,353] [login_test_resolve.py(52)]: sezzle PASS
[2025-03-06 13:52:54,288] [login_test_resolve.py(52)]: sezzle PASS
[2025-03-06 13:52:56,894] [login_test_resolve.py(52)]: sezzle PASS
[2025-03-06 13:52:59,626] [login_test_resolve.py(52)]: sezzle PASS
[2025-03-06 13:53:02,858] [login_test_resolve.py(52)]: shopline PASS
[2025-03-06 13:53:05,684] [login_test_resolve.py(52)]: shopline PASS
[2025-03-06 13:53:08,690] [login_test_resolve.py(52)]: shopline PASS
[2025-03-06 13:53:11,575] [login_test_resolve.py(52)]: shopline PASS
[2025-03-06 13:53:14,389] [login_test_resolve.py(52)]: shopshops PASS
[2025-03-06 13:53:17,301] [login_test_resolve.py(52)]: shopshops PASS
[2025-03-06 13:53:19,633] [login_test_resolve.py(52)]: shopshops PASS
[2025-03-06 13:53:22,572] [login_test_resolve.py(52)]: shopshops PASS
[2025-03-06 13:53:26,797] [login_test_resolve.py(54)]: ParcelPanel FAIL —— data : ['ParcelPanel', 'xie@seel.com', '#ppblingtest1089']
[2025-03-06 13:53:30,006] [login_test_resolve.py(52)]: ParcelPanel PASS
[2025-03-06 13:53:33,334] [login_test_resolve.py(52)]: ParcelPanel PASS
[2025-03-06 13:53:36,652] [login_test_resolve.py(52)]: ParcelPanel PASS
[2025-03-06 13:53:36,798] [result.py(172)]: 测试执行通过： testlogin (login_test_resolve.Auto_Test.testlogin)
[2025-03-06 13:53:36,798] [result.py(96)]: 测试结束： testlogin (login_test_resolve.Auto_Test.testlogin)
[2025-03-06 13:53:36,798] [result.py(97)]: 耗时： 238.54483890533447
[2025-03-06 13:53:36,798] [test_runner.py(213)]: 
Pass	testlogin (login_test_resolve.Auto_Test.testlogin)

[2025-03-06 13:53:36,799] [test_runner.py(233)]: 
测试结束！
运行时间: 0:03:58.738234
共计执行用例数量：1
执行成功用例数量：1
执行失败用例数量：0
跳过执行用例数量：0
产生异常用例数量：0

[2025-03-06 14:15:47,298] [test_runner.py(164)]: 预计并发线程数：3
[2025-03-06 14:15:47,298] [result.py(73)]: 开始测试： testlogin (login_test_resolve.Auto_Test.testlogin)
[2025-03-06 14:15:53,785] [login_test_resolve.py(54)]: shoplazza FAIL —— data : ['shoplazza', 'customer@email.us', '00003195']
[2025-03-06 14:16:03,289] [login_test_resolve.py(52)]: shoplazza PASS
[2025-03-06 14:16:06,164] [login_test_resolve.py(52)]: shoplazza PASS
[2025-03-06 14:16:07,634] [login_test_resolve.py(54)]: shoplazza FAIL —— data : ['shoplazza', '+8613106683312', '2024123089200005970294557']
[2025-03-06 14:16:07,635] [connectionpool.py(868)]: Retrying (Retry(total=2, connect=None, read=None, redirect=None, status=None)) after connection broken by 'NewConnectionError('<urllib3.connection.HTTPConnection object at 0x1055d0f50>: Failed to establish a new connection: [Errno 61] Connection refused')': /session/bca77be9e6d664bd52d89e5c0d70c701/url
[2025-03-06 14:16:07,637] [connectionpool.py(868)]: Retrying (Retry(total=1, connect=None, read=None, redirect=None, status=None)) after connection broken by 'NewConnectionError('<urllib3.connection.HTTPConnection object at 0x1055d1810>: Failed to establish a new connection: [Errno 61] Connection refused')': /session/bca77be9e6d664bd52d89e5c0d70c701/url
[2025-03-06 14:16:07,640] [connectionpool.py(868)]: Retrying (Retry(total=0, connect=None, read=None, redirect=None, status=None)) after connection broken by 'NewConnectionError('<urllib3.connection.HTTPConnection object at 0x10553efd0>: Failed to establish a new connection: [Errno 61] Connection refused')': /session/bca77be9e6d664bd52d89e5c0d70c701/url
[2025-03-06 14:16:07,641] [login_test_resolve.py(54)]: onekingslane FAIL —— data : ['onekingslane', 'juan@seel.com', 'OrderNOkkxlo1739509787012']
[2025-03-06 14:16:07,641] [connectionpool.py(868)]: Retrying (Retry(total=2, connect=None, read=None, redirect=None, status=None)) after connection broken by 'NewConnectionError('<urllib3.connection.HTTPConnection object at 0x1055879b0>: Failed to establish a new connection: [Errno 61] Connection refused')': /session/bca77be9e6d664bd52d89e5c0d70c701/url
[2025-03-06 14:16:07,642] [connectionpool.py(868)]: Retrying (Retry(total=1, connect=None, read=None, redirect=None, status=None)) after connection broken by 'NewConnectionError('<urllib3.connection.HTTPConnection object at 0x1055cae00>: Failed to establish a new connection: [Errno 61] Connection refused')': /session/bca77be9e6d664bd52d89e5c0d70c701/url
[2025-03-06 14:16:07,642] [connectionpool.py(868)]: Retrying (Retry(total=0, connect=None, read=None, redirect=None, status=None)) after connection broken by 'NewConnectionError('<urllib3.connection.HTTPConnection object at 0x1055cb130>: Failed to establish a new connection: [Errno 61] Connection refused')': /session/bca77be9e6d664bd52d89e5c0d70c701/url
[2025-03-06 14:16:07,643] [login_test_resolve.py(54)]: onekingslane FAIL —— data : ['onekingslane', 'juan@seel.com', '2025021471000001858721906']
[2025-03-06 14:16:07,644] [connectionpool.py(868)]: Retrying (Retry(total=2, connect=None, read=None, redirect=None, status=None)) after connection broken by 'NewConnectionError('<urllib3.connection.HTTPConnection object at 0x1055cb790>: Failed to establish a new connection: [Errno 61] Connection refused')': /session/bca77be9e6d664bd52d89e5c0d70c701/url
[2025-03-06 14:16:07,644] [connectionpool.py(868)]: Retrying (Retry(total=1, connect=None, read=None, redirect=None, status=None)) after connection broken by 'NewConnectionError('<urllib3.connection.HTTPConnection object at 0x1055cb9b0>: Failed to establish a new connection: [Errno 61] Connection refused')': /session/bca77be9e6d664bd52d89e5c0d70c701/url
[2025-03-06 14:16:07,644] [connectionpool.py(868)]: Retrying (Retry(total=0, connect=None, read=None, redirect=None, status=None)) after connection broken by 'NewConnectionError('<urllib3.connection.HTTPConnection object at 0x1055cbbd0>: Failed to establish a new connection: [Errno 61] Connection refused')': /session/bca77be9e6d664bd52d89e5c0d70c701/url
[2025-03-06 14:16:07,645] [login_test_resolve.py(54)]: onekingslane FAIL —— data : ['onekingslane', '+8618770004458', 'OrderNOkkxlo1739509787012']
[2025-03-06 14:16:07,645] [connectionpool.py(868)]: Retrying (Retry(total=2, connect=None, read=None, redirect=None, status=None)) after connection broken by 'NewConnectionError('<urllib3.connection.HTTPConnection object at 0x10569c160>: Failed to establish a new connection: [Errno 61] Connection refused')': /session/bca77be9e6d664bd52d89e5c0d70c701/url
[2025-03-06 14:16:07,645] [connectionpool.py(868)]: Retrying (Retry(total=1, connect=None, read=None, redirect=None, status=None)) after connection broken by 'NewConnectionError('<urllib3.connection.HTTPConnection object at 0x10569c380>: Failed to establish a new connection: [Errno 61] Connection refused')': /session/bca77be9e6d664bd52d89e5c0d70c701/url
[2025-03-06 14:16:07,646] [connectionpool.py(868)]: Retrying (Retry(total=0, connect=None, read=None, redirect=None, status=None)) after connection broken by 'NewConnectionError('<urllib3.connection.HTTPConnection object at 0x10569c5a0>: Failed to establish a new connection: [Errno 61] Connection refused')': /session/bca77be9e6d664bd52d89e5c0d70c701/url
[2025-03-06 14:16:07,647] [login_test_resolve.py(54)]: onekingslane FAIL —— data : ['onekingslane', '+8618770004458', '2025021471000001858721906']
[2025-03-06 14:16:07,647] [connectionpool.py(868)]: Retrying (Retry(total=2, connect=None, read=None, redirect=None, status=None)) after connection broken by 'NewConnectionError('<urllib3.connection.HTTPConnection object at 0x1055cbbd0>: Failed to establish a new connection: [Errno 61] Connection refused')': /session/bca77be9e6d664bd52d89e5c0d70c701/url
[2025-03-06 14:16:07,647] [connectionpool.py(868)]: Retrying (Retry(total=1, connect=None, read=None, redirect=None, status=None)) after connection broken by 'NewConnectionError('<urllib3.connection.HTTPConnection object at 0x1055cb9b0>: Failed to establish a new connection: [Errno 61] Connection refused')': /session/bca77be9e6d664bd52d89e5c0d70c701/url
[2025-03-06 14:16:07,647] [connectionpool.py(868)]: Retrying (Retry(total=0, connect=None, read=None, redirect=None, status=None)) after connection broken by 'NewConnectionError('<urllib3.connection.HTTPConnection object at 0x1055cb790>: Failed to establish a new connection: [Errno 61] Connection refused')': /session/bca77be9e6d664bd52d89e5c0d70c701/url
[2025-03-06 14:16:07,648] [login_test_resolve.py(54)]: curtsy FAIL —— data : ['curtsy', 'lin@seel.com', 'asdfghjklqwe72']
[2025-03-06 14:16:07,648] [connectionpool.py(868)]: Retrying (Retry(total=2, connect=None, read=None, redirect=None, status=None)) after connection broken by 'NewConnectionError('<urllib3.connection.HTTPConnection object at 0x1055cb460>: Failed to establish a new connection: [Errno 61] Connection refused')': /session/bca77be9e6d664bd52d89e5c0d70c701/url
[2025-03-06 14:16:07,648] [connectionpool.py(868)]: Retrying (Retry(total=1, connect=None, read=None, redirect=None, status=None)) after connection broken by 'NewConnectionError('<urllib3.connection.HTTPConnection object at 0x1055cb130>: Failed to establish a new connection: [Errno 61] Connection refused')': /session/bca77be9e6d664bd52d89e5c0d70c701/url
[2025-03-06 14:16:07,648] [connectionpool.py(868)]: Retrying (Retry(total=0, connect=None, read=None, redirect=None, status=None)) after connection broken by 'NewConnectionError('<urllib3.connection.HTTPConnection object at 0x1055cae00>: Failed to establish a new connection: [Errno 61] Connection refused')': /session/bca77be9e6d664bd52d89e5c0d70c701/url
[2025-03-06 14:16:07,649] [login_test_resolve.py(54)]: curtsy FAIL —— data : ['curtsy', 'lin@seel.com', '2024010301620773119885958']
[2025-03-06 14:16:07,649] [connectionpool.py(868)]: Retrying (Retry(total=2, connect=None, read=None, redirect=None, status=None)) after connection broken by 'NewConnectionError('<urllib3.connection.HTTPConnection object at 0x1055ca9c0>: Failed to establish a new connection: [Errno 61] Connection refused')': /session/bca77be9e6d664bd52d89e5c0d70c701/url
[2025-03-06 14:16:07,649] [connectionpool.py(868)]: Retrying (Retry(total=1, connect=None, read=None, redirect=None, status=None)) after connection broken by 'NewConnectionError('<urllib3.connection.HTTPConnection object at 0x1055ca7a0>: Failed to establish a new connection: [Errno 61] Connection refused')': /session/bca77be9e6d664bd52d89e5c0d70c701/url
[2025-03-06 14:16:07,649] [connectionpool.py(868)]: Retrying (Retry(total=0, connect=None, read=None, redirect=None, status=None)) after connection broken by 'NewConnectionError('<urllib3.connection.HTTPConnection object at 0x1055ca360>: Failed to establish a new connection: [Errno 61] Connection refused')': /session/bca77be9e6d664bd52d89e5c0d70c701/url
[2025-03-06 14:16:07,650] [login_test_resolve.py(54)]: curtsy FAIL —— data : ['curtsy', '+8618770004458', 'asdfghjklqwe72']
[2025-03-06 14:16:07,650] [connectionpool.py(868)]: Retrying (Retry(total=2, connect=None, read=None, redirect=None, status=None)) after connection broken by 'NewConnectionError('<urllib3.connection.HTTPConnection object at 0x10569cc00>: Failed to establish a new connection: [Errno 61] Connection refused')': /session/bca77be9e6d664bd52d89e5c0d70c701/url
[2025-03-06 14:16:07,650] [connectionpool.py(868)]: Retrying (Retry(total=1, connect=None, read=None, redirect=None, status=None)) after connection broken by 'NewConnectionError('<urllib3.connection.HTTPConnection object at 0x10569ce20>: Failed to establish a new connection: [Errno 61] Connection refused')': /session/bca77be9e6d664bd52d89e5c0d70c701/url
[2025-03-06 14:16:07,650] [connectionpool.py(868)]: Retrying (Retry(total=0, connect=None, read=None, redirect=None, status=None)) after connection broken by 'NewConnectionError('<urllib3.connection.HTTPConnection object at 0x10569d040>: Failed to establish a new connection: [Errno 61] Connection refused')': /session/bca77be9e6d664bd52d89e5c0d70c701/url
[2025-03-06 14:16:07,651] [login_test_resolve.py(54)]: curtsy FAIL —— data : ['curtsy', '+8618770004458', '2024010301620773119885958']
[2025-03-06 14:16:07,651] [connectionpool.py(868)]: Retrying (Retry(total=2, connect=None, read=None, redirect=None, status=None)) after connection broken by 'NewConnectionError('<urllib3.connection.HTTPConnection object at 0x10569d590>: Failed to establish a new connection: [Errno 61] Connection refused')': /session/bca77be9e6d664bd52d89e5c0d70c701/url
[2025-03-06 14:16:07,651] [connectionpool.py(868)]: Retrying (Retry(total=1, connect=None, read=None, redirect=None, status=None)) after connection broken by 'NewConnectionError('<urllib3.connection.HTTPConnection object at 0x10569d7b0>: Failed to establish a new connection: [Errno 61] Connection refused')': /session/bca77be9e6d664bd52d89e5c0d70c701/url
[2025-03-06 14:16:07,652] [connectionpool.py(868)]: Retrying (Retry(total=0, connect=None, read=None, redirect=None, status=None)) after connection broken by 'NewConnectionError('<urllib3.connection.HTTPConnection object at 0x10569d9d0>: Failed to establish a new connection: [Errno 61] Connection refused')': /session/bca77be9e6d664bd52d89e5c0d70c701/url
[2025-03-06 14:16:07,652] [login_test_resolve.py(54)]: sidelineswap FAIL —— data : ['sidelineswap', 'xie@seel.com', '5636045000900091102']
[2025-03-06 14:16:07,652] [connectionpool.py(868)]: Retrying (Retry(total=2, connect=None, read=None, redirect=None, status=None)) after connection broken by 'NewConnectionError('<urllib3.connection.HTTPConnection object at 0x10569df20>: Failed to establish a new connection: [Errno 61] Connection refused')': /session/bca77be9e6d664bd52d89e5c0d70c701/url
[2025-03-06 14:16:07,653] [connectionpool.py(868)]: Retrying (Retry(total=1, connect=None, read=None, redirect=None, status=None)) after connection broken by 'NewConnectionError('<urllib3.connection.HTTPConnection object at 0x10569e140>: Failed to establish a new connection: [Errno 61] Connection refused')': /session/bca77be9e6d664bd52d89e5c0d70c701/url
[2025-03-06 14:16:07,653] [connectionpool.py(868)]: Retrying (Retry(total=0, connect=None, read=None, redirect=None, status=None)) after connection broken by 'NewConnectionError('<urllib3.connection.HTTPConnection object at 0x10569e360>: Failed to establish a new connection: [Errno 61] Connection refused')': /session/bca77be9e6d664bd52d89e5c0d70c701/url
[2025-03-06 14:16:07,653] [login_test_resolve.py(54)]: sidelineswap FAIL —— data : ['sidelineswap', 'xie@seel.com', '2024121701102932097471613']
[2025-03-06 14:16:07,654] [connectionpool.py(868)]: Retrying (Retry(total=2, connect=None, read=None, redirect=None, status=None)) after connection broken by 'NewConnectionError('<urllib3.connection.HTTPConnection object at 0x10569e8b0>: Failed to establish a new connection: [Errno 61] Connection refused')': /session/bca77be9e6d664bd52d89e5c0d70c701/url
[2025-03-06 14:16:07,654] [connectionpool.py(868)]: Retrying (Retry(total=1, connect=None, read=None, redirect=None, status=None)) after connection broken by 'NewConnectionError('<urllib3.connection.HTTPConnection object at 0x10569ead0>: Failed to establish a new connection: [Errno 61] Connection refused')': /session/bca77be9e6d664bd52d89e5c0d70c701/url
[2025-03-06 14:16:07,654] [connectionpool.py(868)]: Retrying (Retry(total=0, connect=None, read=None, redirect=None, status=None)) after connection broken by 'NewConnectionError('<urllib3.connection.HTTPConnection object at 0x10569ecf0>: Failed to establish a new connection: [Errno 61] Connection refused')': /session/bca77be9e6d664bd52d89e5c0d70c701/url
[2025-03-06 14:16:07,654] [login_test_resolve.py(54)]: sidelineswap FAIL —— data : ['sidelineswap', '+8618770004458', '5636045000900091102']
[2025-03-06 14:16:07,654] [connectionpool.py(868)]: Retrying (Retry(total=2, connect=None, read=None, redirect=None, status=None)) after connection broken by 'NewConnectionError('<urllib3.connection.HTTPConnection object at 0x10569f240>: Failed to establish a new connection: [Errno 61] Connection refused')': /session/bca77be9e6d664bd52d89e5c0d70c701/url
[2025-03-06 14:16:07,655] [connectionpool.py(868)]: Retrying (Retry(total=1, connect=None, read=None, redirect=None, status=None)) after connection broken by 'NewConnectionError('<urllib3.connection.HTTPConnection object at 0x10569f460>: Failed to establish a new connection: [Errno 61] Connection refused')': /session/bca77be9e6d664bd52d89e5c0d70c701/url
[2025-03-06 14:16:07,655] [connectionpool.py(868)]: Retrying (Retry(total=0, connect=None, read=None, redirect=None, status=None)) after connection broken by 'NewConnectionError('<urllib3.connection.HTTPConnection object at 0x10569f680>: Failed to establish a new connection: [Errno 61] Connection refused')': /session/bca77be9e6d664bd52d89e5c0d70c701/url
[2025-03-06 14:16:07,655] [login_test_resolve.py(54)]: sidelineswap FAIL —— data : ['sidelineswap', '+8618770004458', '2024121701102932097471613']
[2025-03-06 14:16:07,655] [connectionpool.py(868)]: Retrying (Retry(total=2, connect=None, read=None, redirect=None, status=None)) after connection broken by 'NewConnectionError('<urllib3.connection.HTTPConnection object at 0x10569fbd0>: Failed to establish a new connection: [Errno 61] Connection refused')': /session/bca77be9e6d664bd52d89e5c0d70c701/url
[2025-03-06 14:16:07,656] [connectionpool.py(868)]: Retrying (Retry(total=1, connect=None, read=None, redirect=None, status=None)) after connection broken by 'NewConnectionError('<urllib3.connection.HTTPConnection object at 0x10569fdf0>: Failed to establish a new connection: [Errno 61] Connection refused')': /session/bca77be9e6d664bd52d89e5c0d70c701/url
[2025-03-06 14:16:07,656] [connectionpool.py(868)]: Retrying (Retry(total=0, connect=None, read=None, redirect=None, status=None)) after connection broken by 'NewConnectionError('<urllib3.connection.HTTPConnection object at 0x1056d0050>: Failed to establish a new connection: [Errno 61] Connection refused')': /session/bca77be9e6d664bd52d89e5c0d70c701/url
[2025-03-06 14:16:07,656] [login_test_resolve.py(54)]: shoppremiumoutlets FAIL —— data : ['shoppremiumoutlets', 'xie@seel.com', 'SPO281735238']
[2025-03-06 14:16:07,656] [connectionpool.py(868)]: Retrying (Retry(total=2, connect=None, read=None, redirect=None, status=None)) after connection broken by 'NewConnectionError('<urllib3.connection.HTTPConnection object at 0x1056d05a0>: Failed to establish a new connection: [Errno 61] Connection refused')': /session/bca77be9e6d664bd52d89e5c0d70c701/url
[2025-03-06 14:16:07,657] [connectionpool.py(868)]: Retrying (Retry(total=1, connect=None, read=None, redirect=None, status=None)) after connection broken by 'NewConnectionError('<urllib3.connection.HTTPConnection object at 0x1056d07c0>: Failed to establish a new connection: [Errno 61] Connection refused')': /session/bca77be9e6d664bd52d89e5c0d70c701/url
[2025-03-06 14:16:07,657] [connectionpool.py(868)]: Retrying (Retry(total=0, connect=None, read=None, redirect=None, status=None)) after connection broken by 'NewConnectionError('<urllib3.connection.HTTPConnection object at 0x1056d09e0>: Failed to establish a new connection: [Errno 61] Connection refused')': /session/bca77be9e6d664bd52d89e5c0d70c701/url
[2025-03-06 14:16:07,657] [login_test_resolve.py(54)]: shoppremiumoutlets FAIL —— data : ['shoppremiumoutlets', 'xie@seel.com', '2024121934400003802166798']
[2025-03-06 14:16:07,658] [connectionpool.py(868)]: Retrying (Retry(total=2, connect=None, read=None, redirect=None, status=None)) after connection broken by 'NewConnectionError('<urllib3.connection.HTTPConnection object at 0x10569fbd0>: Failed to establish a new connection: [Errno 61] Connection refused')': /session/bca77be9e6d664bd52d89e5c0d70c701/url
[2025-03-06 14:16:07,658] [connectionpool.py(868)]: Retrying (Retry(total=1, connect=None, read=None, redirect=None, status=None)) after connection broken by 'NewConnectionError('<urllib3.connection.HTTPConnection object at 0x10569fac0>: Failed to establish a new connection: [Errno 61] Connection refused')': /session/bca77be9e6d664bd52d89e5c0d70c701/url
[2025-03-06 14:16:07,658] [connectionpool.py(868)]: Retrying (Retry(total=0, connect=None, read=None, redirect=None, status=None)) after connection broken by 'NewConnectionError('<urllib3.connection.HTTPConnection object at 0x10569f9b0>: Failed to establish a new connection: [Errno 61] Connection refused')': /session/bca77be9e6d664bd52d89e5c0d70c701/url
[2025-03-06 14:16:07,658] [login_test_resolve.py(54)]: shoppremiumoutlets FAIL —— data : ['shoppremiumoutlets', '+8618770004458', 'SPO281735238']
[2025-03-06 14:16:07,659] [connectionpool.py(868)]: Retrying (Retry(total=2, connect=None, read=None, redirect=None, status=None)) after connection broken by 'NewConnectionError('<urllib3.connection.HTTPConnection object at 0x10569f240>: Failed to establish a new connection: [Errno 61] Connection refused')': /session/bca77be9e6d664bd52d89e5c0d70c701/url
[2025-03-06 14:16:07,659] [connectionpool.py(868)]: Retrying (Retry(total=1, connect=None, read=None, redirect=None, status=None)) after connection broken by 'NewConnectionError('<urllib3.connection.HTTPConnection object at 0x10569f130>: Failed to establish a new connection: [Errno 61] Connection refused')': /session/bca77be9e6d664bd52d89e5c0d70c701/url
[2025-03-06 14:16:07,659] [connectionpool.py(868)]: Retrying (Retry(total=0, connect=None, read=None, redirect=None, status=None)) after connection broken by 'NewConnectionError('<urllib3.connection.HTTPConnection object at 0x10569f020>: Failed to establish a new connection: [Errno 61] Connection refused')': /session/bca77be9e6d664bd52d89e5c0d70c701/url
[2025-03-06 14:16:07,660] [login_test_resolve.py(54)]: shoppremiumoutlets FAIL —— data : ['shoppremiumoutlets', '+8618770004458', '2024121934400003802166798']
[2025-03-06 14:16:07,660] [connectionpool.py(868)]: Retrying (Retry(total=2, connect=None, read=None, redirect=None, status=None)) after connection broken by 'NewConnectionError('<urllib3.connection.HTTPConnection object at 0x10569e8b0>: Failed to establish a new connection: [Errno 61] Connection refused')': /session/bca77be9e6d664bd52d89e5c0d70c701/url
[2025-03-06 14:16:07,660] [connectionpool.py(868)]: Retrying (Retry(total=1, connect=None, read=None, redirect=None, status=None)) after connection broken by 'NewConnectionError('<urllib3.connection.HTTPConnection object at 0x10569e7a0>: Failed to establish a new connection: [Errno 61] Connection refused')': /session/bca77be9e6d664bd52d89e5c0d70c701/url
[2025-03-06 14:16:07,661] [connectionpool.py(868)]: Retrying (Retry(total=0, connect=None, read=None, redirect=None, status=None)) after connection broken by 'NewConnectionError('<urllib3.connection.HTTPConnection object at 0x10569e690>: Failed to establish a new connection: [Errno 61] Connection refused')': /session/bca77be9e6d664bd52d89e5c0d70c701/url
[2025-03-06 14:16:07,662] [login_test_resolve.py(54)]: backcountry FAIL —— data : ['backcountry', 'juan@seel.com', 'OrderNOximrp1739509842513']
[2025-03-06 14:16:07,668] [connectionpool.py(868)]: Retrying (Retry(total=2, connect=None, read=None, redirect=None, status=None)) after connection broken by 'NewConnectionError('<urllib3.connection.HTTPConnection object at 0x10569df20>: Failed to establish a new connection: [Errno 61] Connection refused')': /session/bca77be9e6d664bd52d89e5c0d70c701/url
[2025-03-06 14:16:07,669] [connectionpool.py(868)]: Retrying (Retry(total=1, connect=None, read=None, redirect=None, status=None)) after connection broken by 'NewConnectionError('<urllib3.connection.HTTPConnection object at 0x10569dbf0>: Failed to establish a new connection: [Errno 61] Connection refused')': /session/bca77be9e6d664bd52d89e5c0d70c701/url
[2025-03-06 14:16:07,676] [connectionpool.py(868)]: Retrying (Retry(total=0, connect=None, read=None, redirect=None, status=None)) after connection broken by 'NewConnectionError('<urllib3.connection.HTTPConnection object at 0x10569d9d0>: Failed to establish a new connection: [Errno 61] Connection refused')': /session/bca77be9e6d664bd52d89e5c0d70c701/url
[2025-03-06 14:16:07,681] [login_test_resolve.py(54)]: backcountry FAIL —— data : ['backcountry', 'juan@seel.com', '2025021471000001864271894']
[2025-03-06 14:16:07,682] [connectionpool.py(868)]: Retrying (Retry(total=2, connect=None, read=None, redirect=None, status=None)) after connection broken by 'NewConnectionError('<urllib3.connection.HTTPConnection object at 0x10569d6a0>: Failed to establish a new connection: [Errno 61] Connection refused')': /session/bca77be9e6d664bd52d89e5c0d70c701/url
[2025-03-06 14:16:07,687] [connectionpool.py(868)]: Retrying (Retry(total=1, connect=None, read=None, redirect=None, status=None)) after connection broken by 'NewConnectionError('<urllib3.connection.HTTPConnection object at 0x10569d260>: Failed to establish a new connection: [Errno 61] Connection refused')': /session/bca77be9e6d664bd52d89e5c0d70c701/url
[2025-03-06 14:16:07,688] [connectionpool.py(868)]: Retrying (Retry(total=0, connect=None, read=None, redirect=None, status=None)) after connection broken by 'NewConnectionError('<urllib3.connection.HTTPConnection object at 0x10569d040>: Failed to establish a new connection: [Errno 61] Connection refused')': /session/bca77be9e6d664bd52d89e5c0d70c701/url
[2025-03-06 14:16:07,688] [login_test_resolve.py(54)]: backcountry FAIL —— data : ['backcountry', '+8618770004458', 'OrderNOximrp1739509842513']
[2025-03-06 14:16:07,688] [connectionpool.py(868)]: Retrying (Retry(total=2, connect=None, read=None, redirect=None, status=None)) after connection broken by 'NewConnectionError('<urllib3.connection.HTTPConnection object at 0x10569cd10>: Failed to establish a new connection: [Errno 61] Connection refused')': /session/bca77be9e6d664bd52d89e5c0d70c701/url
[2025-03-06 14:16:07,689] [connectionpool.py(868)]: Retrying (Retry(total=1, connect=None, read=None, redirect=None, status=None)) after connection broken by 'NewConnectionError('<urllib3.connection.HTTPConnection object at 0x10569c8d0>: Failed to establish a new connection: [Errno 61] Connection refused')': /session/bca77be9e6d664bd52d89e5c0d70c701/url
[2025-03-06 14:16:07,689] [connectionpool.py(868)]: Retrying (Retry(total=0, connect=None, read=None, redirect=None, status=None)) after connection broken by 'NewConnectionError('<urllib3.connection.HTTPConnection object at 0x10569c050>: Failed to establish a new connection: [Errno 61] Connection refused')': /session/bca77be9e6d664bd52d89e5c0d70c701/url
[2025-03-06 14:16:07,689] [login_test_resolve.py(54)]: backcountry FAIL —— data : ['backcountry', '+8618770004458', '2025021471000001864271894']
[2025-03-06 14:16:07,689] [connectionpool.py(868)]: Retrying (Retry(total=2, connect=None, read=None, redirect=None, status=None)) after connection broken by 'NewConnectionError('<urllib3.connection.HTTPConnection object at 0x1055ca9c0>: Failed to establish a new connection: [Errno 61] Connection refused')': /session/bca77be9e6d664bd52d89e5c0d70c701/url
[2025-03-06 14:16:07,690] [connectionpool.py(868)]: Retrying (Retry(total=1, connect=None, read=None, redirect=None, status=None)) after connection broken by 'NewConnectionError('<urllib3.connection.HTTPConnection object at 0x1055caad0>: Failed to establish a new connection: [Errno 61] Connection refused')': /session/bca77be9e6d664bd52d89e5c0d70c701/url
[2025-03-06 14:16:07,690] [connectionpool.py(868)]: Retrying (Retry(total=0, connect=None, read=None, redirect=None, status=None)) after connection broken by 'NewConnectionError('<urllib3.connection.HTTPConnection object at 0x1055cabe0>: Failed to establish a new connection: [Errno 61] Connection refused')': /session/bca77be9e6d664bd52d89e5c0d70c701/url
[2025-03-06 14:16:07,691] [login_test_resolve.py(54)]: chicv FAIL —— data : ['chicv', 'juan@seel.com', 'OrderNOrehsn1739956270417']
[2025-03-06 14:16:07,691] [connectionpool.py(868)]: Retrying (Retry(total=2, connect=None, read=None, redirect=None, status=None)) after connection broken by 'NewConnectionError('<urllib3.connection.HTTPConnection object at 0x1055cb460>: Failed to establish a new connection: [Errno 61] Connection refused')': /session/bca77be9e6d664bd52d89e5c0d70c701/url
[2025-03-06 14:16:07,691] [connectionpool.py(868)]: Retrying (Retry(total=1, connect=None, read=None, redirect=None, status=None)) after connection broken by 'NewConnectionError('<urllib3.connection.HTTPConnection object at 0x1055cb350>: Failed to establish a new connection: [Errno 61] Connection refused')': /session/bca77be9e6d664bd52d89e5c0d70c701/url
[2025-03-06 14:16:07,691] [connectionpool.py(868)]: Retrying (Retry(total=0, connect=None, read=None, redirect=None, status=None)) after connection broken by 'NewConnectionError('<urllib3.connection.HTTPConnection object at 0x1055cb020>: Failed to establish a new connection: [Errno 61] Connection refused')': /session/bca77be9e6d664bd52d89e5c0d70c701/url
[2025-03-06 14:16:07,692] [login_test_resolve.py(54)]: chicv FAIL —— data : ['chicv', 'juan@seel.com', '2025021999300003307065337']
[2025-03-06 14:16:07,692] [connectionpool.py(868)]: Retrying (Retry(total=2, connect=None, read=None, redirect=None, status=None)) after connection broken by 'NewConnectionError('<urllib3.connection.HTTPConnection object at 0x1055cbbd0>: Failed to establish a new connection: [Errno 61] Connection refused')': /session/bca77be9e6d664bd52d89e5c0d70c701/url
[2025-03-06 14:16:07,692] [connectionpool.py(868)]: Retrying (Retry(total=1, connect=None, read=None, redirect=None, status=None)) after connection broken by 'NewConnectionError('<urllib3.connection.HTTPConnection object at 0x1055cbdf0>: Failed to establish a new connection: [Errno 61] Connection refused')': /session/bca77be9e6d664bd52d89e5c0d70c701/url
[2025-03-06 14:16:07,692] [connectionpool.py(868)]: Retrying (Retry(total=0, connect=None, read=None, redirect=None, status=None)) after connection broken by 'NewConnectionError('<urllib3.connection.HTTPConnection object at 0x1056d0270>: Failed to establish a new connection: [Errno 61] Connection refused')': /session/bca77be9e6d664bd52d89e5c0d70c701/url
[2025-03-06 14:16:07,693] [login_test_resolve.py(54)]: chicv FAIL —— data : ['chicv', '+8618770004458', 'OrderNOrehsn1739956270417']
[2025-03-06 14:16:07,693] [connectionpool.py(868)]: Retrying (Retry(total=2, connect=None, read=None, redirect=None, status=None)) after connection broken by 'NewConnectionError('<urllib3.connection.HTTPConnection object at 0x1056d0e20>: Failed to establish a new connection: [Errno 61] Connection refused')': /session/bca77be9e6d664bd52d89e5c0d70c701/url
[2025-03-06 14:16:07,693] [connectionpool.py(868)]: Retrying (Retry(total=1, connect=None, read=None, redirect=None, status=None)) after connection broken by 'NewConnectionError('<urllib3.connection.HTTPConnection object at 0x1056d1040>: Failed to establish a new connection: [Errno 61] Connection refused')': /session/bca77be9e6d664bd52d89e5c0d70c701/url
[2025-03-06 14:16:07,693] [connectionpool.py(868)]: Retrying (Retry(total=0, connect=None, read=None, redirect=None, status=None)) after connection broken by 'NewConnectionError('<urllib3.connection.HTTPConnection object at 0x1056d1260>: Failed to establish a new connection: [Errno 61] Connection refused')': /session/bca77be9e6d664bd52d89e5c0d70c701/url
[2025-03-06 14:16:07,694] [login_test_resolve.py(54)]: chicv FAIL —— data : ['chicv', '+8618770004458', '2025021999300003307065337']
[2025-03-06 14:16:07,694] [connectionpool.py(868)]: Retrying (Retry(total=2, connect=None, read=None, redirect=None, status=None)) after connection broken by 'NewConnectionError('<urllib3.connection.HTTPConnection object at 0x1056d17b0>: Failed to establish a new connection: [Errno 61] Connection refused')': /session/bca77be9e6d664bd52d89e5c0d70c701/url
[2025-03-06 14:16:07,694] [connectionpool.py(868)]: Retrying (Retry(total=1, connect=None, read=None, redirect=None, status=None)) after connection broken by 'NewConnectionError('<urllib3.connection.HTTPConnection object at 0x1056d19d0>: Failed to establish a new connection: [Errno 61] Connection refused')': /session/bca77be9e6d664bd52d89e5c0d70c701/url
[2025-03-06 14:16:07,697] [connectionpool.py(868)]: Retrying (Retry(total=0, connect=None, read=None, redirect=None, status=None)) after connection broken by 'NewConnectionError('<urllib3.connection.HTTPConnection object at 0x1055cbdf0>: Failed to establish a new connection: [Errno 61] Connection refused')': /session/bca77be9e6d664bd52d89e5c0d70c701/url
[2025-03-06 14:16:07,698] [login_test_resolve.py(54)]: commentsold FAIL —— data : ['commentsold', 'juan@seel.com', 'OrderNOyqioq1739509786744']
[2025-03-06 14:16:07,698] [connectionpool.py(868)]: Retrying (Retry(total=2, connect=None, read=None, redirect=None, status=None)) after connection broken by 'NewConnectionError('<urllib3.connection.HTTPConnection object at 0x1055cb9b0>: Failed to establish a new connection: [Errno 61] Connection refused')': /session/bca77be9e6d664bd52d89e5c0d70c701/url
[2025-03-06 14:16:07,698] [connectionpool.py(868)]: Retrying (Retry(total=1, connect=None, read=None, redirect=None, status=None)) after connection broken by 'NewConnectionError('<urllib3.connection.HTTPConnection object at 0x1055cb790>: Failed to establish a new connection: [Errno 61] Connection refused')': /session/bca77be9e6d664bd52d89e5c0d70c701/url
[2025-03-06 14:16:07,698] [connectionpool.py(868)]: Retrying (Retry(total=0, connect=None, read=None, redirect=None, status=None)) after connection broken by 'NewConnectionError('<urllib3.connection.HTTPConnection object at 0x1055cb680>: Failed to establish a new connection: [Errno 61] Connection refused')': /session/bca77be9e6d664bd52d89e5c0d70c701/url
[2025-03-06 14:16:07,699] [login_test_resolve.py(54)]: commentsold FAIL —— data : ['commentsold', 'juan@seel.com', '2025021471000001858697910']
[2025-03-06 14:16:07,699] [connectionpool.py(868)]: Retrying (Retry(total=2, connect=None, read=None, redirect=None, status=None)) after connection broken by 'NewConnectionError('<urllib3.connection.HTTPConnection object at 0x1055cb130>: Failed to establish a new connection: [Errno 61] Connection refused')': /session/bca77be9e6d664bd52d89e5c0d70c701/url
[2025-03-06 14:16:07,699] [connectionpool.py(868)]: Retrying (Retry(total=1, connect=None, read=None, redirect=None, status=None)) after connection broken by 'NewConnectionError('<urllib3.connection.HTTPConnection object at 0x1055cae00>: Failed to establish a new connection: [Errno 61] Connection refused')': /session/bca77be9e6d664bd52d89e5c0d70c701/url
[2025-03-06 14:16:07,699] [connectionpool.py(868)]: Retrying (Retry(total=0, connect=None, read=None, redirect=None, status=None)) after connection broken by 'NewConnectionError('<urllib3.connection.HTTPConnection object at 0x1055cacf0>: Failed to establish a new connection: [Errno 61] Connection refused')': /session/bca77be9e6d664bd52d89e5c0d70c701/url
[2025-03-06 14:16:07,700] [login_test_resolve.py(54)]: commentsold FAIL —— data : ['commentsold', '+8618770004458', 'OrderNOyqioq1739509786744']
[2025-03-06 14:16:07,700] [connectionpool.py(868)]: Retrying (Retry(total=2, connect=None, read=None, redirect=None, status=None)) after connection broken by 'NewConnectionError('<urllib3.connection.HTTPConnection object at 0x1055ca7a0>: Failed to establish a new connection: [Errno 61] Connection refused')': /session/bca77be9e6d664bd52d89e5c0d70c701/url
[2025-03-06 14:16:07,701] [connectionpool.py(868)]: Retrying (Retry(total=1, connect=None, read=None, redirect=None, status=None)) after connection broken by 'NewConnectionError('<urllib3.connection.HTTPConnection object at 0x10569c050>: Failed to establish a new connection: [Errno 61] Connection refused')': /session/bca77be9e6d664bd52d89e5c0d70c701/url
[2025-03-06 14:16:07,702] [connectionpool.py(868)]: Retrying (Retry(total=0, connect=None, read=None, redirect=None, status=None)) after connection broken by 'NewConnectionError('<urllib3.connection.HTTPConnection object at 0x10569c8d0>: Failed to establish a new connection: [Errno 61] Connection refused')': /session/bca77be9e6d664bd52d89e5c0d70c701/url
[2025-03-06 14:16:07,702] [login_test_resolve.py(54)]: commentsold FAIL —— data : ['commentsold', '+8618770004458', '2025021471000001858697910']
[2025-03-06 14:16:07,703] [connectionpool.py(868)]: Retrying (Retry(total=2, connect=None, read=None, redirect=None, status=None)) after connection broken by 'NewConnectionError('<urllib3.connection.HTTPConnection object at 0x10569ce20>: Failed to establish a new connection: [Errno 61] Connection refused')': /session/bca77be9e6d664bd52d89e5c0d70c701/url
[2025-03-06 14:16:07,703] [connectionpool.py(868)]: Retrying (Retry(total=1, connect=None, read=None, redirect=None, status=None)) after connection broken by 'NewConnectionError('<urllib3.connection.HTTPConnection object at 0x10569d040>: Failed to establish a new connection: [Errno 61] Connection refused')': /session/bca77be9e6d664bd52d89e5c0d70c701/url
[2025-03-06 14:16:07,703] [connectionpool.py(868)]: Retrying (Retry(total=0, connect=None, read=None, redirect=None, status=None)) after connection broken by 'NewConnectionError('<urllib3.connection.HTTPConnection object at 0x10569d260>: Failed to establish a new connection: [Errno 61] Connection refused')': /session/bca77be9e6d664bd52d89e5c0d70c701/url
[2025-03-06 14:16:07,703] [login_test_resolve.py(54)]: ctbids FAIL —— data : ['ctbids', 'juan@seel.com', 'OrderNOphdqx1739938617487']
[2025-03-06 14:16:07,704] [connectionpool.py(868)]: Retrying (Retry(total=2, connect=None, read=None, redirect=None, status=None)) after connection broken by 'NewConnectionError('<urllib3.connection.HTTPConnection object at 0x10569d7b0>: Failed to establish a new connection: [Errno 61] Connection refused')': /session/bca77be9e6d664bd52d89e5c0d70c701/url
[2025-03-06 14:16:07,704] [connectionpool.py(868)]: Retrying (Retry(total=1, connect=None, read=None, redirect=None, status=None)) after connection broken by 'NewConnectionError('<urllib3.connection.HTTPConnection object at 0x10569d9d0>: Failed to establish a new connection: [Errno 61] Connection refused')': /session/bca77be9e6d664bd52d89e5c0d70c701/url
[2025-03-06 14:16:07,704] [connectionpool.py(868)]: Retrying (Retry(total=0, connect=None, read=None, redirect=None, status=None)) after connection broken by 'NewConnectionError('<urllib3.connection.HTTPConnection object at 0x10569dbf0>: Failed to establish a new connection: [Errno 61] Connection refused')': /session/bca77be9e6d664bd52d89e5c0d70c701/url
[2025-03-06 14:16:07,704] [login_test_resolve.py(54)]: ctbids FAIL —— data : ['ctbids', 'juan@seel.com', '2025021999300001541791253']
[2025-03-06 14:16:07,705] [connectionpool.py(868)]: Retrying (Retry(total=2, connect=None, read=None, redirect=None, status=None)) after connection broken by 'NewConnectionError('<urllib3.connection.HTTPConnection object at 0x10569e470>: Failed to establish a new connection: [Errno 61] Connection refused')': /session/bca77be9e6d664bd52d89e5c0d70c701/url
[2025-03-06 14:16:07,705] [connectionpool.py(868)]: Retrying (Retry(total=1, connect=None, read=None, redirect=None, status=None)) after connection broken by 'NewConnectionError('<urllib3.connection.HTTPConnection object at 0x10569e690>: Failed to establish a new connection: [Errno 61] Connection refused')': /session/bca77be9e6d664bd52d89e5c0d70c701/url
[2025-03-06 14:16:07,705] [connectionpool.py(868)]: Retrying (Retry(total=0, connect=None, read=None, redirect=None, status=None)) after connection broken by 'NewConnectionError('<urllib3.connection.HTTPConnection object at 0x10569e7a0>: Failed to establish a new connection: [Errno 61] Connection refused')': /session/bca77be9e6d664bd52d89e5c0d70c701/url
[2025-03-06 14:16:07,705] [login_test_resolve.py(54)]: ctbids FAIL —— data : ['ctbids', '+8618770004458', 'OrderNOphdqx1739938617487']
[2025-03-06 14:16:07,705] [connectionpool.py(868)]: Retrying (Retry(total=2, connect=None, read=None, redirect=None, status=None)) after connection broken by 'NewConnectionError('<urllib3.connection.HTTPConnection object at 0x10569ee00>: Failed to establish a new connection: [Errno 61] Connection refused')': /session/bca77be9e6d664bd52d89e5c0d70c701/url
[2025-03-06 14:16:07,706] [connectionpool.py(868)]: Retrying (Retry(total=1, connect=None, read=None, redirect=None, status=None)) after connection broken by 'NewConnectionError('<urllib3.connection.HTTPConnection object at 0x10569f020>: Failed to establish a new connection: [Errno 61] Connection refused')': /session/bca77be9e6d664bd52d89e5c0d70c701/url
[2025-03-06 14:16:07,706] [connectionpool.py(868)]: Retrying (Retry(total=0, connect=None, read=None, redirect=None, status=None)) after connection broken by 'NewConnectionError('<urllib3.connection.HTTPConnection object at 0x10569f130>: Failed to establish a new connection: [Errno 61] Connection refused')': /session/bca77be9e6d664bd52d89e5c0d70c701/url
[2025-03-06 14:16:07,706] [login_test_resolve.py(54)]: ctbids FAIL —— data : ['ctbids', '+8618770004458', '2025021999300001541791253']
[2025-03-06 14:16:07,706] [connectionpool.py(868)]: Retrying (Retry(total=2, connect=None, read=None, redirect=None, status=None)) after connection broken by 'NewConnectionError('<urllib3.connection.HTTPConnection object at 0x10569f790>: Failed to establish a new connection: [Errno 61] Connection refused')': /session/bca77be9e6d664bd52d89e5c0d70c701/url
[2025-03-06 14:16:07,707] [connectionpool.py(868)]: Retrying (Retry(total=1, connect=None, read=None, redirect=None, status=None)) after connection broken by 'NewConnectionError('<urllib3.connection.HTTPConnection object at 0x10569f9b0>: Failed to establish a new connection: [Errno 61] Connection refused')': /session/bca77be9e6d664bd52d89e5c0d70c701/url
[2025-03-06 14:16:07,707] [connectionpool.py(868)]: Retrying (Retry(total=0, connect=None, read=None, redirect=None, status=None)) after connection broken by 'NewConnectionError('<urllib3.connection.HTTPConnection object at 0x10569fac0>: Failed to establish a new connection: [Errno 61] Connection refused')': /session/bca77be9e6d664bd52d89e5c0d70c701/url
[2025-03-06 14:16:07,707] [login_test_resolve.py(54)]: goodwillfinds FAIL —— data : ['goodwillfinds', 'juan@seel.com', 'OrderNOsyfmj1739941882264']
[2025-03-06 14:16:07,708] [connectionpool.py(868)]: Retrying (Retry(total=2, connect=None, read=None, redirect=None, status=None)) after connection broken by 'NewConnectionError('<urllib3.connection.HTTPConnection object at 0x10569fdf0>: Failed to establish a new connection: [Errno 61] Connection refused')': /session/bca77be9e6d664bd52d89e5c0d70c701/url
[2025-03-06 14:16:07,708] [connectionpool.py(868)]: Retrying (Retry(total=1, connect=None, read=None, redirect=None, status=None)) after connection broken by 'NewConnectionError('<urllib3.connection.HTTPConnection object at 0x10569c5a0>: Failed to establish a new connection: [Errno 61] Connection refused')': /session/bca77be9e6d664bd52d89e5c0d70c701/url
[2025-03-06 14:16:07,709] [connectionpool.py(868)]: Retrying (Retry(total=0, connect=None, read=None, redirect=None, status=None)) after connection broken by 'NewConnectionError('<urllib3.connection.HTTPConnection object at 0x10569c380>: Failed to establish a new connection: [Errno 61] Connection refused')': /session/bca77be9e6d664bd52d89e5c0d70c701/url
[2025-03-06 14:16:07,709] [login_test_resolve.py(54)]: goodwillfinds FAIL —— data : ['goodwillfinds', 'juan@seel.com', '2025021999300001868258262']
[2025-03-06 14:16:07,709] [connectionpool.py(868)]: Retrying (Retry(total=2, connect=None, read=None, redirect=None, status=None)) after connection broken by 'NewConnectionError('<urllib3.connection.HTTPConnection object at 0x105402690>: Failed to establish a new connection: [Errno 61] Connection refused')': /session/bca77be9e6d664bd52d89e5c0d70c701/url
[2025-03-06 14:16:07,710] [connectionpool.py(868)]: Retrying (Retry(total=1, connect=None, read=None, redirect=None, status=None)) after connection broken by 'NewConnectionError('<urllib3.connection.HTTPConnection object at 0x105403460>: Failed to establish a new connection: [Errno 61] Connection refused')': /session/bca77be9e6d664bd52d89e5c0d70c701/url
[2025-03-06 14:16:07,710] [connectionpool.py(868)]: Retrying (Retry(total=0, connect=None, read=None, redirect=None, status=None)) after connection broken by 'NewConnectionError('<urllib3.connection.HTTPConnection object at 0x105401bf0>: Failed to establish a new connection: [Errno 61] Connection refused')': /session/bca77be9e6d664bd52d89e5c0d70c701/url
[2025-03-06 14:16:07,710] [login_test_resolve.py(54)]: goodwillfinds FAIL —— data : ['goodwillfinds', '+8618770004458', 'OrderNOsyfmj1739941882264']
[2025-03-06 14:16:07,711] [connectionpool.py(868)]: Retrying (Retry(total=2, connect=None, read=None, redirect=None, status=None)) after connection broken by 'NewConnectionError('<urllib3.connection.HTTPConnection object at 0x105403680>: Failed to establish a new connection: [Errno 61] Connection refused')': /session/bca77be9e6d664bd52d89e5c0d70c701/url
[2025-03-06 14:16:07,711] [connectionpool.py(868)]: Retrying (Retry(total=1, connect=None, read=None, redirect=None, status=None)) after connection broken by 'NewConnectionError('<urllib3.connection.HTTPConnection object at 0x105402f10>: Failed to establish a new connection: [Errno 61] Connection refused')': /session/bca77be9e6d664bd52d89e5c0d70c701/url
[2025-03-06 14:16:07,712] [connectionpool.py(868)]: Retrying (Retry(total=0, connect=None, read=None, redirect=None, status=None)) after connection broken by 'NewConnectionError('<urllib3.connection.HTTPConnection object at 0x10569c380>: Failed to establish a new connection: [Errno 61] Connection refused')': /session/bca77be9e6d664bd52d89e5c0d70c701/url
[2025-03-06 14:16:07,712] [login_test_resolve.py(54)]: goodwillfinds FAIL —— data : ['goodwillfinds', '+8618770004458', '2025021999300001868258262']
[2025-03-06 14:16:07,712] [connectionpool.py(868)]: Retrying (Retry(total=2, connect=None, read=None, redirect=None, status=None)) after connection broken by 'NewConnectionError('<urllib3.connection.HTTPConnection object at 0x10569c6b0>: Failed to establish a new connection: [Errno 61] Connection refused')': /session/bca77be9e6d664bd52d89e5c0d70c701/url
[2025-03-06 14:16:07,713] [connectionpool.py(868)]: Retrying (Retry(total=1, connect=None, read=None, redirect=None, status=None)) after connection broken by 'NewConnectionError('<urllib3.connection.HTTPConnection object at 0x10569fbd0>: Failed to establish a new connection: [Errno 61] Connection refused')': /session/bca77be9e6d664bd52d89e5c0d70c701/url
[2025-03-06 14:16:07,713] [connectionpool.py(868)]: Retrying (Retry(total=0, connect=None, read=None, redirect=None, status=None)) after connection broken by 'NewConnectionError('<urllib3.connection.HTTPConnection object at 0x10569fac0>: Failed to establish a new connection: [Errno 61] Connection refused')': /session/bca77be9e6d664bd52d89e5c0d70c701/url
[2025-03-06 14:16:07,713] [login_test_resolve.py(54)]: jeulia FAIL —— data : ['jeulia', 'tongshuai.jia@seel.com', 'test_orderid_1739859142']
[2025-03-06 14:16:07,713] [connectionpool.py(868)]: Retrying (Retry(total=2, connect=None, read=None, redirect=None, status=None)) after connection broken by 'NewConnectionError('<urllib3.connection.HTTPConnection object at 0x10569f460>: Failed to establish a new connection: [Errno 61] Connection refused')': /session/bca77be9e6d664bd52d89e5c0d70c701/url
[2025-03-06 14:16:07,713] [connectionpool.py(868)]: Retrying (Retry(total=1, connect=None, read=None, redirect=None, status=None)) after connection broken by 'NewConnectionError('<urllib3.connection.HTTPConnection object at 0x10569f240>: Failed to establish a new connection: [Errno 61] Connection refused')': /session/bca77be9e6d664bd52d89e5c0d70c701/url
[2025-03-06 14:16:07,714] [connectionpool.py(868)]: Retrying (Retry(total=0, connect=None, read=None, redirect=None, status=None)) after connection broken by 'NewConnectionError('<urllib3.connection.HTTPConnection object at 0x10569f130>: Failed to establish a new connection: [Errno 61] Connection refused')': /session/bca77be9e6d664bd52d89e5c0d70c701/url
[2025-03-06 14:16:07,714] [login_test_resolve.py(54)]: jeulia FAIL —— data : ['jeulia', 'tongshuai.jia@seel.com', '2025021855800002234612189']
[2025-03-06 14:16:07,714] [connectionpool.py(868)]: Retrying (Retry(total=2, connect=None, read=None, redirect=None, status=None)) after connection broken by 'NewConnectionError('<urllib3.connection.HTTPConnection object at 0x10569ead0>: Failed to establish a new connection: [Errno 61] Connection refused')': /session/bca77be9e6d664bd52d89e5c0d70c701/url
[2025-03-06 14:16:07,714] [connectionpool.py(868)]: Retrying (Retry(total=1, connect=None, read=None, redirect=None, status=None)) after connection broken by 'NewConnectionError('<urllib3.connection.HTTPConnection object at 0x10569e8b0>: Failed to establish a new connection: [Errno 61] Connection refused')': /session/bca77be9e6d664bd52d89e5c0d70c701/url
[2025-03-06 14:16:07,715] [connectionpool.py(868)]: Retrying (Retry(total=0, connect=None, read=None, redirect=None, status=None)) after connection broken by 'NewConnectionError('<urllib3.connection.HTTPConnection object at 0x10569e7a0>: Failed to establish a new connection: [Errno 61] Connection refused')': /session/bca77be9e6d664bd52d89e5c0d70c701/url
[2025-03-06 14:16:07,715] [login_test_resolve.py(54)]: jeulia FAIL —— data : ['jeulia', '+8618770004458', 'test_orderid_1739859142']
[2025-03-06 14:16:07,715] [connectionpool.py(868)]: Retrying (Retry(total=2, connect=None, read=None, redirect=None, status=None)) after connection broken by 'NewConnectionError('<urllib3.connection.HTTPConnection object at 0x10569e140>: Failed to establish a new connection: [Errno 61] Connection refused')': /session/bca77be9e6d664bd52d89e5c0d70c701/url
[2025-03-06 14:16:07,716] [connectionpool.py(868)]: Retrying (Retry(total=1, connect=None, read=None, redirect=None, status=None)) after connection broken by 'NewConnectionError('<urllib3.connection.HTTPConnection object at 0x10569df20>: Failed to establish a new connection: [Errno 61] Connection refused')': /session/bca77be9e6d664bd52d89e5c0d70c701/url
[2025-03-06 14:16:07,716] [connectionpool.py(868)]: Retrying (Retry(total=0, connect=None, read=None, redirect=None, status=None)) after connection broken by 'NewConnectionError('<urllib3.connection.HTTPConnection object at 0x10569dbf0>: Failed to establish a new connection: [Errno 61] Connection refused')': /session/bca77be9e6d664bd52d89e5c0d70c701/url
[2025-03-06 14:16:07,716] [login_test_resolve.py(54)]: jeulia FAIL —— data : ['jeulia', '+8618770004458', '2025021855800002234612189']
[2025-03-06 14:16:07,716] [connectionpool.py(868)]: Retrying (Retry(total=2, connect=None, read=None, redirect=None, status=None)) after connection broken by 'NewConnectionError('<urllib3.connection.HTTPConnection object at 0x10569d8c0>: Failed to establish a new connection: [Errno 61] Connection refused')': /session/bca77be9e6d664bd52d89e5c0d70c701/url
[2025-03-06 14:16:07,716] [connectionpool.py(868)]: Retrying (Retry(total=1, connect=None, read=None, redirect=None, status=None)) after connection broken by 'NewConnectionError('<urllib3.connection.HTTPConnection object at 0x10569d6a0>: Failed to establish a new connection: [Errno 61] Connection refused')': /session/bca77be9e6d664bd52d89e5c0d70c701/url
[2025-03-06 14:16:07,717] [connectionpool.py(868)]: Retrying (Retry(total=0, connect=None, read=None, redirect=None, status=None)) after connection broken by 'NewConnectionError('<urllib3.connection.HTTPConnection object at 0x10569d260>: Failed to establish a new connection: [Errno 61] Connection refused')': /session/bca77be9e6d664bd52d89e5c0d70c701/url
[2025-03-06 14:16:07,717] [login_test_resolve.py(54)]: luxedujour FAIL —— data : ['luxedujour', 'juan@seel.com', 'OrderNOsddko1739941610930']
[2025-03-06 14:16:07,717] [connectionpool.py(868)]: Retrying (Retry(total=2, connect=None, read=None, redirect=None, status=None)) after connection broken by 'NewConnectionError('<urllib3.connection.HTTPConnection object at 0x10569cf30>: Failed to establish a new connection: [Errno 61] Connection refused')': /session/bca77be9e6d664bd52d89e5c0d70c701/url
[2025-03-06 14:16:07,718] [connectionpool.py(868)]: Retrying (Retry(total=1, connect=None, read=None, redirect=None, status=None)) after connection broken by 'NewConnectionError('<urllib3.connection.HTTPConnection object at 0x10569cd10>: Failed to establish a new connection: [Errno 61] Connection refused')': /session/bca77be9e6d664bd52d89e5c0d70c701/url
[2025-03-06 14:16:07,718] [connectionpool.py(868)]: Retrying (Retry(total=0, connect=None, read=None, redirect=None, status=None)) after connection broken by 'NewConnectionError('<urllib3.connection.HTTPConnection object at 0x10569c8d0>: Failed to establish a new connection: [Errno 61] Connection refused')': /session/bca77be9e6d664bd52d89e5c0d70c701/url
[2025-03-06 14:16:07,718] [login_test_resolve.py(54)]: luxedujour FAIL —— data : ['luxedujour', 'juan@seel.com', '2025021999300001841115947']
[2025-03-06 14:16:07,718] [connectionpool.py(868)]: Retrying (Retry(total=2, connect=None, read=None, redirect=None, status=None)) after connection broken by 'NewConnectionError('<urllib3.connection.HTTPConnection object at 0x1055cbf00>: Failed to establish a new connection: [Errno 61] Connection refused')': /session/bca77be9e6d664bd52d89e5c0d70c701/url
[2025-03-06 14:16:07,719] [connectionpool.py(868)]: Retrying (Retry(total=1, connect=None, read=None, redirect=None, status=None)) after connection broken by 'NewConnectionError('<urllib3.connection.HTTPConnection object at 0x1055ca8b0>: Failed to establish a new connection: [Errno 61] Connection refused')': /session/bca77be9e6d664bd52d89e5c0d70c701/url
[2025-03-06 14:16:07,719] [connectionpool.py(868)]: Retrying (Retry(total=0, connect=None, read=None, redirect=None, status=None)) after connection broken by 'NewConnectionError('<urllib3.connection.HTTPConnection object at 0x1055cacf0>: Failed to establish a new connection: [Errno 61] Connection refused')': /session/bca77be9e6d664bd52d89e5c0d70c701/url
[2025-03-06 14:16:07,719] [login_test_resolve.py(54)]: luxedujour FAIL —— data : ['luxedujour', '+8618770004458', 'OrderNOsddko1739941610930']
[2025-03-06 14:16:07,719] [connectionpool.py(868)]: Retrying (Retry(total=2, connect=None, read=None, redirect=None, status=None)) after connection broken by 'NewConnectionError('<urllib3.connection.HTTPConnection object at 0x1055cabe0>: Failed to establish a new connection: [Errno 61] Connection refused')': /session/bca77be9e6d664bd52d89e5c0d70c701/url
[2025-03-06 14:16:07,720] [connectionpool.py(868)]: Retrying (Retry(total=1, connect=None, read=None, redirect=None, status=None)) after connection broken by 'NewConnectionError('<urllib3.connection.HTTPConnection object at 0x1055cb570>: Failed to establish a new connection: [Errno 61] Connection refused')': /session/bca77be9e6d664bd52d89e5c0d70c701/url
[2025-03-06 14:16:07,720] [connectionpool.py(868)]: Retrying (Retry(total=0, connect=None, read=None, redirect=None, status=None)) after connection broken by 'NewConnectionError('<urllib3.connection.HTTPConnection object at 0x1055cb680>: Failed to establish a new connection: [Errno 61] Connection refused')': /session/bca77be9e6d664bd52d89e5c0d70c701/url
[2025-03-06 14:16:07,720] [login_test_resolve.py(54)]: luxedujour FAIL —— data : ['luxedujour', '+8618770004458', '2025021999300001841115947']
[2025-03-06 14:16:07,720] [connectionpool.py(868)]: Retrying (Retry(total=2, connect=None, read=None, redirect=None, status=None)) after connection broken by 'NewConnectionError('<urllib3.connection.HTTPConnection object at 0x1055cb020>: Failed to establish a new connection: [Errno 61] Connection refused')': /session/bca77be9e6d664bd52d89e5c0d70c701/url
[2025-03-06 14:16:07,721] [connectionpool.py(868)]: Retrying (Retry(total=1, connect=None, read=None, redirect=None, status=None)) after connection broken by 'NewConnectionError('<urllib3.connection.HTTPConnection object at 0x1055cbac0>: Failed to establish a new connection: [Errno 61] Connection refused')': /session/bca77be9e6d664bd52d89e5c0d70c701/url
[2025-03-06 14:16:07,721] [connectionpool.py(868)]: Retrying (Retry(total=0, connect=None, read=None, redirect=None, status=None)) after connection broken by 'NewConnectionError('<urllib3.connection.HTTPConnection object at 0x1055cbbd0>: Failed to establish a new connection: [Errno 61] Connection refused')': /session/bca77be9e6d664bd52d89e5c0d70c701/url
[2025-03-06 14:16:07,721] [login_test_resolve.py(54)]: poizon FAIL —— data : ['poizon', 'juan@seel.com', 'OrderNOzyeuo1739959796244']
[2025-03-06 14:16:07,721] [connectionpool.py(868)]: Retrying (Retry(total=2, connect=None, read=None, redirect=None, status=None)) after connection broken by 'NewConnectionError('<urllib3.connection.HTTPConnection object at 0x1054028b0>: Failed to establish a new connection: [Errno 61] Connection refused')': /session/bca77be9e6d664bd52d89e5c0d70c701/url
[2025-03-06 14:16:07,722] [connectionpool.py(868)]: Retrying (Retry(total=1, connect=None, read=None, redirect=None, status=None)) after connection broken by 'NewConnectionError('<urllib3.connection.HTTPConnection object at 0x105402470>: Failed to establish a new connection: [Errno 61] Connection refused')': /session/bca77be9e6d664bd52d89e5c0d70c701/url
[2025-03-06 14:16:07,722] [connectionpool.py(868)]: Retrying (Retry(total=0, connect=None, read=None, redirect=None, status=None)) after connection broken by 'NewConnectionError('<urllib3.connection.HTTPConnection object at 0x105401ae0>: Failed to establish a new connection: [Errno 61] Connection refused')': /session/bca77be9e6d664bd52d89e5c0d70c701/url
[2025-03-06 14:16:07,722] [login_test_resolve.py(54)]: poizon FAIL —— data : ['poizon', 'juan@seel.com', '2025021999300003659637792']
[2025-03-06 14:16:07,723] [connectionpool.py(868)]: Retrying (Retry(total=2, connect=None, read=None, redirect=None, status=None)) after connection broken by 'NewConnectionError('<urllib3.connection.HTTPConnection object at 0x105400e20>: Failed to establish a new connection: [Errno 61] Connection refused')': /session/bca77be9e6d664bd52d89e5c0d70c701/url
[2025-03-06 14:16:07,723] [connectionpool.py(868)]: Retrying (Retry(total=1, connect=None, read=None, redirect=None, status=None)) after connection broken by 'NewConnectionError('<urllib3.connection.HTTPConnection object at 0x1055cbbd0>: Failed to establish a new connection: [Errno 61] Connection refused')': /session/bca77be9e6d664bd52d89e5c0d70c701/url
[2025-03-06 14:16:07,723] [connectionpool.py(868)]: Retrying (Retry(total=0, connect=None, read=None, redirect=None, status=None)) after connection broken by 'NewConnectionError('<urllib3.connection.HTTPConnection object at 0x1055cbdf0>: Failed to establish a new connection: [Errno 61] Connection refused')': /session/bca77be9e6d664bd52d89e5c0d70c701/url
[2025-03-06 14:16:07,723] [login_test_resolve.py(54)]: poizon FAIL —— data : ['poizon', '+8618770004458', 'OrderNOzyeuo1739959796244']
[2025-03-06 14:16:07,724] [connectionpool.py(868)]: Retrying (Retry(total=2, connect=None, read=None, redirect=None, status=None)) after connection broken by 'NewConnectionError('<urllib3.connection.HTTPConnection object at 0x1055cb350>: Failed to establish a new connection: [Errno 61] Connection refused')': /session/bca77be9e6d664bd52d89e5c0d70c701/url
[2025-03-06 14:16:07,724] [connectionpool.py(868)]: Retrying (Retry(total=1, connect=None, read=None, redirect=None, status=None)) after connection broken by 'NewConnectionError('<urllib3.connection.HTTPConnection object at 0x1055cb460>: Failed to establish a new connection: [Errno 61] Connection refused')': /session/bca77be9e6d664bd52d89e5c0d70c701/url
[2025-03-06 14:16:07,724] [connectionpool.py(868)]: Retrying (Retry(total=0, connect=None, read=None, redirect=None, status=None)) after connection broken by 'NewConnectionError('<urllib3.connection.HTTPConnection object at 0x1055cb240>: Failed to establish a new connection: [Errno 61] Connection refused')': /session/bca77be9e6d664bd52d89e5c0d70c701/url
[2025-03-06 14:16:07,724] [login_test_resolve.py(54)]: poizon FAIL —— data : ['poizon', '+8618770004458', '2025021999300003659637792']
[2025-03-06 14:16:07,725] [connectionpool.py(868)]: Retrying (Retry(total=2, connect=None, read=None, redirect=None, status=None)) after connection broken by 'NewConnectionError('<urllib3.connection.HTTPConnection object at 0x1055caad0>: Failed to establish a new connection: [Errno 61] Connection refused')': /session/bca77be9e6d664bd52d89e5c0d70c701/url
[2025-03-06 14:16:07,725] [connectionpool.py(868)]: Retrying (Retry(total=1, connect=None, read=None, redirect=None, status=None)) after connection broken by 'NewConnectionError('<urllib3.connection.HTTPConnection object at 0x1055ca9c0>: Failed to establish a new connection: [Errno 61] Connection refused')': /session/bca77be9e6d664bd52d89e5c0d70c701/url
[2025-03-06 14:16:07,725] [connectionpool.py(868)]: Retrying (Retry(total=0, connect=None, read=None, redirect=None, status=None)) after connection broken by 'NewConnectionError('<urllib3.connection.HTTPConnection object at 0x1055ca690>: Failed to establish a new connection: [Errno 61] Connection refused')': /session/bca77be9e6d664bd52d89e5c0d70c701/url
[2025-03-06 14:16:07,725] [login_test_resolve.py(54)]: sezzle FAIL —— data : ['sezzle', 'lei.xing@seel.com', 'OrderNO1736332340']
[2025-03-06 14:16:07,726] [connectionpool.py(868)]: Retrying (Retry(total=2, connect=None, read=None, redirect=None, status=None)) after connection broken by 'NewConnectionError('<urllib3.connection.HTTPConnection object at 0x10569c7c0>: Failed to establish a new connection: [Errno 61] Connection refused')': /session/bca77be9e6d664bd52d89e5c0d70c701/url
[2025-03-06 14:16:07,726] [connectionpool.py(868)]: Retrying (Retry(total=1, connect=None, read=None, redirect=None, status=None)) after connection broken by 'NewConnectionError('<urllib3.connection.HTTPConnection object at 0x10569c9e0>: Failed to establish a new connection: [Errno 61] Connection refused')': /session/bca77be9e6d664bd52d89e5c0d70c701/url
[2025-03-06 14:16:07,726] [connectionpool.py(868)]: Retrying (Retry(total=0, connect=None, read=None, redirect=None, status=None)) after connection broken by 'NewConnectionError('<urllib3.connection.HTTPConnection object at 0x10569caf0>: Failed to establish a new connection: [Errno 61] Connection refused')': /session/bca77be9e6d664bd52d89e5c0d70c701/url
[2025-03-06 14:16:07,726] [login_test_resolve.py(54)]: sezzle FAIL —— data : ['sezzle', 'lei.xing@seel.com', '2025010878500003794061907']
[2025-03-06 14:16:07,726] [connectionpool.py(868)]: Retrying (Retry(total=2, connect=None, read=None, redirect=None, status=None)) after connection broken by 'NewConnectionError('<urllib3.connection.HTTPConnection object at 0x10569d150>: Failed to establish a new connection: [Errno 61] Connection refused')': /session/bca77be9e6d664bd52d89e5c0d70c701/url
[2025-03-06 14:16:07,727] [connectionpool.py(868)]: Retrying (Retry(total=1, connect=None, read=None, redirect=None, status=None)) after connection broken by 'NewConnectionError('<urllib3.connection.HTTPConnection object at 0x10569d370>: Failed to establish a new connection: [Errno 61] Connection refused')': /session/bca77be9e6d664bd52d89e5c0d70c701/url
[2025-03-06 14:16:07,727] [connectionpool.py(868)]: Retrying (Retry(total=0, connect=None, read=None, redirect=None, status=None)) after connection broken by 'NewConnectionError('<urllib3.connection.HTTPConnection object at 0x10569d480>: Failed to establish a new connection: [Errno 61] Connection refused')': /session/bca77be9e6d664bd52d89e5c0d70c701/url
[2025-03-06 14:16:07,727] [login_test_resolve.py(54)]: sezzle FAIL —— data : ['sezzle', '+8618770004458', 'OrderNO1736332340']
[2025-03-06 14:16:07,727] [connectionpool.py(868)]: Retrying (Retry(total=2, connect=None, read=None, redirect=None, status=None)) after connection broken by 'NewConnectionError('<urllib3.connection.HTTPConnection object at 0x10569dae0>: Failed to establish a new connection: [Errno 61] Connection refused')': /session/bca77be9e6d664bd52d89e5c0d70c701/url
[2025-03-06 14:16:07,727] [connectionpool.py(868)]: Retrying (Retry(total=1, connect=None, read=None, redirect=None, status=None)) after connection broken by 'NewConnectionError('<urllib3.connection.HTTPConnection object at 0x10569dd00>: Failed to establish a new connection: [Errno 61] Connection refused')': /session/bca77be9e6d664bd52d89e5c0d70c701/url
[2025-03-06 14:16:07,728] [connectionpool.py(868)]: Retrying (Retry(total=0, connect=None, read=None, redirect=None, status=None)) after connection broken by 'NewConnectionError('<urllib3.connection.HTTPConnection object at 0x10569de10>: Failed to establish a new connection: [Errno 61] Connection refused')': /session/bca77be9e6d664bd52d89e5c0d70c701/url
[2025-03-06 14:16:07,728] [login_test_resolve.py(54)]: sezzle FAIL —— data : ['sezzle', '+8618770004458', '2025010878500003794061907']
[2025-03-06 14:16:07,728] [connectionpool.py(868)]: Retrying (Retry(total=2, connect=None, read=None, redirect=None, status=None)) after connection broken by 'NewConnectionError('<urllib3.connection.HTTPConnection object at 0x10569e360>: Failed to establish a new connection: [Errno 61] Connection refused')': /session/bca77be9e6d664bd52d89e5c0d70c701/url
[2025-03-06 14:16:07,728] [connectionpool.py(868)]: Retrying (Retry(total=1, connect=None, read=None, redirect=None, status=None)) after connection broken by 'NewConnectionError('<urllib3.connection.HTTPConnection object at 0x10569e580>: Failed to establish a new connection: [Errno 61] Connection refused')': /session/bca77be9e6d664bd52d89e5c0d70c701/url
[2025-03-06 14:16:07,729] [connectionpool.py(868)]: Retrying (Retry(total=0, connect=None, read=None, redirect=None, status=None)) after connection broken by 'NewConnectionError('<urllib3.connection.HTTPConnection object at 0x10569e9c0>: Failed to establish a new connection: [Errno 61] Connection refused')': /session/bca77be9e6d664bd52d89e5c0d70c701/url
[2025-03-06 14:16:07,729] [login_test_resolve.py(54)]: shopline FAIL —— data : ['shopline', 'juan@seel.com', 'OrderNOgvlhf1739956369615']
[2025-03-06 14:16:07,729] [connectionpool.py(868)]: Retrying (Retry(total=2, connect=None, read=None, redirect=None, status=None)) after connection broken by 'NewConnectionError('<urllib3.connection.HTTPConnection object at 0x10569ecf0>: Failed to establish a new connection: [Errno 61] Connection refused')': /session/bca77be9e6d664bd52d89e5c0d70c701/url
[2025-03-06 14:16:07,729] [connectionpool.py(868)]: Retrying (Retry(total=1, connect=None, read=None, redirect=None, status=None)) after connection broken by 'NewConnectionError('<urllib3.connection.HTTPConnection object at 0x10569ef10>: Failed to establish a new connection: [Errno 61] Connection refused')': /session/bca77be9e6d664bd52d89e5c0d70c701/url
[2025-03-06 14:16:07,730] [connectionpool.py(868)]: Retrying (Retry(total=0, connect=None, read=None, redirect=None, status=None)) after connection broken by 'NewConnectionError('<urllib3.connection.HTTPConnection object at 0x10569f350>: Failed to establish a new connection: [Errno 61] Connection refused')': /session/bca77be9e6d664bd52d89e5c0d70c701/url
[2025-03-06 14:16:07,730] [login_test_resolve.py(54)]: shopline FAIL —— data : ['shopline', 'juan@seel.com', '2025021999300003316982083']
[2025-03-06 14:16:07,730] [connectionpool.py(868)]: Retrying (Retry(total=2, connect=None, read=None, redirect=None, status=None)) after connection broken by 'NewConnectionError('<urllib3.connection.HTTPConnection object at 0x10569f680>: Failed to establish a new connection: [Errno 61] Connection refused')': /session/bca77be9e6d664bd52d89e5c0d70c701/url
[2025-03-06 14:16:07,730] [connectionpool.py(868)]: Retrying (Retry(total=1, connect=None, read=None, redirect=None, status=None)) after connection broken by 'NewConnectionError('<urllib3.connection.HTTPConnection object at 0x10569f8a0>: Failed to establish a new connection: [Errno 61] Connection refused')': /session/bca77be9e6d664bd52d89e5c0d70c701/url
[2025-03-06 14:16:07,731] [connectionpool.py(868)]: Retrying (Retry(total=0, connect=None, read=None, redirect=None, status=None)) after connection broken by 'NewConnectionError('<urllib3.connection.HTTPConnection object at 0x10569fce0>: Failed to establish a new connection: [Errno 61] Connection refused')': /session/bca77be9e6d664bd52d89e5c0d70c701/url
[2025-03-06 14:16:07,731] [login_test_resolve.py(54)]: shopline FAIL —— data : ['shopline', '+8618770004458', 'OrderNOgvlhf1739956369615']
[2025-03-06 14:16:07,731] [connectionpool.py(868)]: Retrying (Retry(total=2, connect=None, read=None, redirect=None, status=None)) after connection broken by 'NewConnectionError('<urllib3.connection.HTTPConnection object at 0x10569c380>: Failed to establish a new connection: [Errno 61] Connection refused')': /session/bca77be9e6d664bd52d89e5c0d70c701/url
[2025-03-06 14:16:07,731] [connectionpool.py(868)]: Retrying (Retry(total=1, connect=None, read=None, redirect=None, status=None)) after connection broken by 'NewConnectionError('<urllib3.connection.HTTPConnection object at 0x10569c160>: Failed to establish a new connection: [Errno 61] Connection refused')': /session/bca77be9e6d664bd52d89e5c0d70c701/url
[2025-03-06 14:16:07,731] [connectionpool.py(868)]: Retrying (Retry(total=0, connect=None, read=None, redirect=None, status=None)) after connection broken by 'NewConnectionError('<urllib3.connection.HTTPConnection object at 0x105402cf0>: Failed to establish a new connection: [Errno 61] Connection refused')': /session/bca77be9e6d664bd52d89e5c0d70c701/url
[2025-03-06 14:16:07,732] [login_test_resolve.py(54)]: shopline FAIL —— data : ['shopline', '+8618770004458', '2025021999300003316982083']
[2025-03-06 14:16:07,732] [connectionpool.py(868)]: Retrying (Retry(total=2, connect=None, read=None, redirect=None, status=None)) after connection broken by 'NewConnectionError('<urllib3.connection.HTTPConnection object at 0x105402690>: Failed to establish a new connection: [Errno 61] Connection refused')': /session/bca77be9e6d664bd52d89e5c0d70c701/url
[2025-03-06 14:16:07,732] [connectionpool.py(868)]: Retrying (Retry(total=1, connect=None, read=None, redirect=None, status=None)) after connection broken by 'NewConnectionError('<urllib3.connection.HTTPConnection object at 0x105403460>: Failed to establish a new connection: [Errno 61] Connection refused')': /session/bca77be9e6d664bd52d89e5c0d70c701/url
[2025-03-06 14:16:07,732] [connectionpool.py(868)]: Retrying (Retry(total=0, connect=None, read=None, redirect=None, status=None)) after connection broken by 'NewConnectionError('<urllib3.connection.HTTPConnection object at 0x1054027a0>: Failed to establish a new connection: [Errno 61] Connection refused')': /session/bca77be9e6d664bd52d89e5c0d70c701/url
[2025-03-06 14:16:07,732] [login_test_resolve.py(54)]: shopshops FAIL —— data : ['shopshops', 'juan@seel.com', 'OrderNOxszbr1739941949045']
[2025-03-06 14:16:07,733] [connectionpool.py(868)]: Retrying (Retry(total=2, connect=None, read=None, redirect=None, status=None)) after connection broken by 'NewConnectionError('<urllib3.connection.HTTPConnection object at 0x105403020>: Failed to establish a new connection: [Errno 61] Connection refused')': /session/bca77be9e6d664bd52d89e5c0d70c701/url
[2025-03-06 14:16:07,733] [connectionpool.py(868)]: Retrying (Retry(total=1, connect=None, read=None, redirect=None, status=None)) after connection broken by 'NewConnectionError('<urllib3.connection.HTTPConnection object at 0x10569c380>: Failed to establish a new connection: [Errno 61] Connection refused')': /session/bca77be9e6d664bd52d89e5c0d70c701/url
[2025-03-06 14:16:07,733] [connectionpool.py(868)]: Retrying (Retry(total=0, connect=None, read=None, redirect=None, status=None)) after connection broken by 'NewConnectionError('<urllib3.connection.HTTPConnection object at 0x10569c490>: Failed to establish a new connection: [Errno 61] Connection refused')': /session/bca77be9e6d664bd52d89e5c0d70c701/url
[2025-03-06 14:16:07,734] [login_test_resolve.py(54)]: shopshops FAIL —— data : ['shopshops', 'juan@seel.com', '2025021999300001874932637']
[2025-03-06 14:16:07,734] [connectionpool.py(868)]: Retrying (Retry(total=2, connect=None, read=None, redirect=None, status=None)) after connection broken by 'NewConnectionError('<urllib3.connection.HTTPConnection object at 0x10569f8a0>: Failed to establish a new connection: [Errno 61] Connection refused')': /session/bca77be9e6d664bd52d89e5c0d70c701/url
[2025-03-06 14:16:07,734] [connectionpool.py(868)]: Retrying (Retry(total=1, connect=None, read=None, redirect=None, status=None)) after connection broken by 'NewConnectionError('<urllib3.connection.HTTPConnection object at 0x10569f680>: Failed to establish a new connection: [Errno 61] Connection refused')': /session/bca77be9e6d664bd52d89e5c0d70c701/url
[2025-03-06 14:16:07,734] [connectionpool.py(868)]: Retrying (Retry(total=0, connect=None, read=None, redirect=None, status=None)) after connection broken by 'NewConnectionError('<urllib3.connection.HTTPConnection object at 0x10569f9b0>: Failed to establish a new connection: [Errno 61] Connection refused')': /session/bca77be9e6d664bd52d89e5c0d70c701/url
[2025-03-06 14:16:07,734] [login_test_resolve.py(54)]: shopshops FAIL —— data : ['shopshops', '+8618770004458', 'OrderNOxszbr1739941949045']
[2025-03-06 14:16:07,735] [connectionpool.py(868)]: Retrying (Retry(total=2, connect=None, read=None, redirect=None, status=None)) after connection broken by 'NewConnectionError('<urllib3.connection.HTTPConnection object at 0x10569ef10>: Failed to establish a new connection: [Errno 61] Connection refused')': /session/bca77be9e6d664bd52d89e5c0d70c701/url
[2025-03-06 14:16:07,735] [connectionpool.py(868)]: Retrying (Retry(total=1, connect=None, read=None, redirect=None, status=None)) after connection broken by 'NewConnectionError('<urllib3.connection.HTTPConnection object at 0x10569ecf0>: Failed to establish a new connection: [Errno 61] Connection refused')': /session/bca77be9e6d664bd52d89e5c0d70c701/url
[2025-03-06 14:16:07,735] [connectionpool.py(868)]: Retrying (Retry(total=0, connect=None, read=None, redirect=None, status=None)) after connection broken by 'NewConnectionError('<urllib3.connection.HTTPConnection object at 0x10569f020>: Failed to establish a new connection: [Errno 61] Connection refused')': /session/bca77be9e6d664bd52d89e5c0d70c701/url
[2025-03-06 14:16:07,735] [login_test_resolve.py(54)]: shopshops FAIL —— data : ['shopshops', '+8618770004458', '2025021999300001874932637']
[2025-03-06 14:16:07,736] [connectionpool.py(868)]: Retrying (Retry(total=2, connect=None, read=None, redirect=None, status=None)) after connection broken by 'NewConnectionError('<urllib3.connection.HTTPConnection object at 0x10569e580>: Failed to establish a new connection: [Errno 61] Connection refused')': /session/bca77be9e6d664bd52d89e5c0d70c701/url
[2025-03-06 14:16:07,736] [connectionpool.py(868)]: Retrying (Retry(total=1, connect=None, read=None, redirect=None, status=None)) after connection broken by 'NewConnectionError('<urllib3.connection.HTTPConnection object at 0x10569e360>: Failed to establish a new connection: [Errno 61] Connection refused')': /session/bca77be9e6d664bd52d89e5c0d70c701/url
[2025-03-06 14:16:07,736] [connectionpool.py(868)]: Retrying (Retry(total=0, connect=None, read=None, redirect=None, status=None)) after connection broken by 'NewConnectionError('<urllib3.connection.HTTPConnection object at 0x10569e690>: Failed to establish a new connection: [Errno 61] Connection refused')': /session/bca77be9e6d664bd52d89e5c0d70c701/url
[2025-03-06 14:16:07,736] [login_test_resolve.py(54)]: ParcelPanel FAIL —— data : ['ParcelPanel', 'xie@seel.com', '#ppblingtest1089']
[2025-03-06 14:16:07,737] [connectionpool.py(868)]: Retrying (Retry(total=2, connect=None, read=None, redirect=None, status=None)) after connection broken by 'NewConnectionError('<urllib3.connection.HTTPConnection object at 0x10569dd00>: Failed to establish a new connection: [Errno 61] Connection refused')': /session/bca77be9e6d664bd52d89e5c0d70c701/url
[2025-03-06 14:16:07,737] [connectionpool.py(868)]: Retrying (Retry(total=1, connect=None, read=None, redirect=None, status=None)) after connection broken by 'NewConnectionError('<urllib3.connection.HTTPConnection object at 0x10569dae0>: Failed to establish a new connection: [Errno 61] Connection refused')': /session/bca77be9e6d664bd52d89e5c0d70c701/url
[2025-03-06 14:16:07,738] [connectionpool.py(868)]: Retrying (Retry(total=0, connect=None, read=None, redirect=None, status=None)) after connection broken by 'NewConnectionError('<urllib3.connection.HTTPConnection object at 0x10569d9d0>: Failed to establish a new connection: [Errno 61] Connection refused')': /session/bca77be9e6d664bd52d89e5c0d70c701/url
[2025-03-06 14:16:07,738] [login_test_resolve.py(54)]: ParcelPanel FAIL —— data : ['ParcelPanel', 'xie@seel.com', '2025010678600002276385871']
[2025-03-06 14:16:07,738] [connectionpool.py(868)]: Retrying (Retry(total=2, connect=None, read=None, redirect=None, status=None)) after connection broken by 'NewConnectionError('<urllib3.connection.HTTPConnection object at 0x10569d370>: Failed to establish a new connection: [Errno 61] Connection refused')': /session/bca77be9e6d664bd52d89e5c0d70c701/url
[2025-03-06 14:16:07,738] [connectionpool.py(868)]: Retrying (Retry(total=1, connect=None, read=None, redirect=None, status=None)) after connection broken by 'NewConnectionError('<urllib3.connection.HTTPConnection object at 0x10569d150>: Failed to establish a new connection: [Errno 61] Connection refused')': /session/bca77be9e6d664bd52d89e5c0d70c701/url
[2025-03-06 14:16:07,738] [connectionpool.py(868)]: Retrying (Retry(total=0, connect=None, read=None, redirect=None, status=None)) after connection broken by 'NewConnectionError('<urllib3.connection.HTTPConnection object at 0x10569d040>: Failed to establish a new connection: [Errno 61] Connection refused')': /session/bca77be9e6d664bd52d89e5c0d70c701/url
[2025-03-06 14:16:07,739] [login_test_resolve.py(54)]: ParcelPanel FAIL —— data : ['ParcelPanel', '+8618770004458', '#ppblingtest1089']
[2025-03-06 14:16:07,739] [connectionpool.py(868)]: Retrying (Retry(total=2, connect=None, read=None, redirect=None, status=None)) after connection broken by 'NewConnectionError('<urllib3.connection.HTTPConnection object at 0x10569c9e0>: Failed to establish a new connection: [Errno 61] Connection refused')': /session/bca77be9e6d664bd52d89e5c0d70c701/url
[2025-03-06 14:16:07,739] [connectionpool.py(868)]: Retrying (Retry(total=1, connect=None, read=None, redirect=None, status=None)) after connection broken by 'NewConnectionError('<urllib3.connection.HTTPConnection object at 0x10569c7c0>: Failed to establish a new connection: [Errno 61] Connection refused')': /session/bca77be9e6d664bd52d89e5c0d70c701/url
[2025-03-06 14:16:07,739] [connectionpool.py(868)]: Retrying (Retry(total=0, connect=None, read=None, redirect=None, status=None)) after connection broken by 'NewConnectionError('<urllib3.connection.HTTPConnection object at 0x10569c050>: Failed to establish a new connection: [Errno 61] Connection refused')': /session/bca77be9e6d664bd52d89e5c0d70c701/url
[2025-03-06 14:16:07,739] [login_test_resolve.py(54)]: ParcelPanel FAIL —— data : ['ParcelPanel', '+8618770004458', '2025010678600002276385871']
[2025-03-06 14:16:07,740] [connectionpool.py(868)]: Retrying (Retry(total=2, connect=None, read=None, redirect=None, status=None)) after connection broken by 'NewConnectionError('<urllib3.connection.HTTPConnection object at 0x1055caad0>: Failed to establish a new connection: [Errno 61] Connection refused')': /session/bca77be9e6d664bd52d89e5c0d70c701
[2025-03-06 14:16:07,740] [connectionpool.py(868)]: Retrying (Retry(total=1, connect=None, read=None, redirect=None, status=None)) after connection broken by 'NewConnectionError('<urllib3.connection.HTTPConnection object at 0x1055cae00>: Failed to establish a new connection: [Errno 61] Connection refused')': /session/bca77be9e6d664bd52d89e5c0d70c701
[2025-03-06 14:16:07,740] [connectionpool.py(868)]: Retrying (Retry(total=0, connect=None, read=None, redirect=None, status=None)) after connection broken by 'NewConnectionError('<urllib3.connection.HTTPConnection object at 0x1055cb130>: Failed to establish a new connection: [Errno 61] Connection refused')': /session/bca77be9e6d664bd52d89e5c0d70c701
[2025-03-06 14:16:07,748] [result.py(172)]: 测试执行通过： testlogin (login_test_resolve.Auto_Test.testlogin)
[2025-03-06 14:16:07,748] [result.py(96)]: 测试结束： testlogin (login_test_resolve.Auto_Test.testlogin)
[2025-03-06 14:16:07,748] [result.py(97)]: 耗时： 20.44906210899353
